<?xml version="1.0"?>
<robot xmlns:sensor="http://playerstage.sourceforge.net/gazebo/xmlschema/#sensor"
       xmlns:controller="http://playerstage.sourceforge.net/gazebo/xmlschema/#controller"
       xmlns:interface="http://playerstage.sourceforge.net/gazebo/xmlschema/#interface"
       xmlns:xacro="http://ros.org/wiki/xacro">

  <xacro:include filename="$(find schunk_description)/urdf/lwa/lwa.gazebo.xacro" />
  <xacro:include filename="$(find schunk_description)/urdf/lwa/lwa.transmission.xacro" />
 
  <!-- calibration -->
  <xacro:include filename="$(find schunk_description)/calibration/calibration.urdf.xacro" />
  <xacro:include filename="$(find schunk_description)/calibration/parameters.urdf.xacro" />

 
  <xacro:macro name="schunk_lwa" params="parent name *origin">

  <joint name="${name}_fix_joint" type="fixed">
    <parent link="${parent}"/>
    <child link="${name}_base"/>
		<insert_block name="origin"/>  
  </joint>

  <link name="${name}_base">
		<inertial>
			<origin xyz="0 0 0" rpy="0 0 0" />
			<mass value="1.00"/>
			<inertia ixx="0.01" ixy="0" ixz="0" iyy="0.01" iyz="0" izz="0.01" />
		</inertial>
  
		<visual>
			<origin xyz="0 0 0" rpy="0 0 0" />
			<geometry>
				<mesh filename="package://schunk_description/meshes/lwa/base.dae" />
			</geometry>
		</visual>

		<collision>
			<origin xyz="0 0 0" rpy="0 0 0" />
			<geometry>
				<mesh filename="package://schunk_description/meshes/lwa/base.dae" />
			</geometry>
		</collision>
	</link>

	<!-- joint between link1 and link2 -->
	<joint name="${name}_1_joint" type="revolute">
		<origin xyz="0 0 0.3" rpy="0 0 0"/>
		<parent link="${name}_base"/>
		<child link="${name}_1_link"/>
		<axis xyz="0 0 1"/>
		<calibration rising="${arm_1_ref}"/>
		<dynamics damping="10" />
		<limit effort="370" velocity="2.0" lower="-3.1415926" upper="3.1415926"/>
		<safety_controller k_position="20" k_velocity="50" soft_lower_limit="${-3.1415926 + 0.01}" soft_upper_limit="${3.1415926 - 0.01}"/>
	</joint>

	<link name="${name}_1_link">
		<inertial>
			<origin xyz="0 0 -0.16" rpy="0 0 0" />
			<!--mass value="1.3487"/-->
			<mass value="${mass_1}"/>
			<inertia ixx="0.01" ixy="0" ixz="0" iyy="0.01" iyz="0" izz="0.01" />
		</inertial>
			
		<visual>
			<origin xyz="0 0 0" rpy="0 0 0" />
			<geometry>
				<mesh filename="package://schunk_description/meshes/lwa/link1.dae" />
			</geometry>
			<color rgba="0.4 0.4 0.3 1.0"/>
		</visual>
			
		<collision>
			<origin xyz="0 0 0" rpy="0 0 0" />
			<geometry>
				<mesh filename="package://schunk_description/meshes/lwa/link1.dae" />
			</geometry>
		</collision>
	</link>

	<!-- joint between arm_1_link and arm_2_link -->	
	<joint name="${name}_2_joint" type="revolute">
		<origin xyz="0 0 0" rpy="-1.5707963 0 0"/>
		<parent link="${name}_1_link"/>
		<child link="${name}_2_link"/>
		<axis xyz="0 0 1"/>
		<calibration rising="${arm_2_ref}"/>
		<dynamics damping="100" />
		<limit effort="370" velocity="2.0" lower="-2.147" upper="2.147"/>
		<safety_controller k_position="20" k_velocity="50" soft_lower_limit="${-2.147 + 0.01}" soft_upper_limit="${2.147 - 0.01}" />
	</joint>

	<link name="${name}_2_link">
		<inertial>
			<origin xyz="0 0 0" rpy="0 0 0"/>
			<!--mass value="5.734939"/-->
			<mass value="${mass_2}"/>
			<inertia ixx="0.03" ixy="0" ixz="0" iyy="0.03" iyz="0" izz="0.03" />
		</inertial>
			
		<visual>
			<origin xyz="0 0 0" rpy="0 0 0" />
			<geometry>
				<mesh filename="package://schunk_description/meshes/lwa/link2.dae" />
			</geometry>
			<material name="Schunk/DarkGolden" />
		</visual>
			
		<collision>
			<origin xyz="0 0 0" rpy="0 0 0" />
			<geometry>
				<mesh filename="package://schunk_description/meshes/lwa/link2.dae"/>
			</geometry>
		</collision>
	</link>

	<!-- joint between arm_2_link and arm_3_link -->	
	<joint name="${name}_3_joint" type="revolute">
		<origin xyz="0 -0.328 0" rpy="1.5707963 0 0"/>
		<parent link="${name}_2_link"/>
		<child link="${name}_3_link"/>
		<axis xyz="0 0 1"/>
		<calibration rising="${arm_3_ref}"/>
		<dynamics damping="5" />
		<limit effort="176" velocity="2.0" lower="-3.1415926" upper="3.1415926"/>
		<safety_controller k_position="20" k_velocity="25" soft_lower_limit="${-3.1415926 + 0.01}" soft_upper_limit="${3.1415926 - 0.01}" />
	</joint>

	<link name="${name}_3_link">
		<inertial>
			<origin xyz="0 0 -0.14064" rpy="0 0 0"/>
			<!--mass value="4.214668"/-->
			<mass value="${mass_3}"/>
			<inertia ixx="0.03" ixy="0" ixz="0" iyy="0.03" iyz="0" izz="0.03" />
		</inertial>
			
		<visual>
			<origin xyz="0 0 0" rpy="0 0 0" />
			<geometry>
				<mesh filename="package://schunk_description/meshes/lwa/link3.dae" />
			</geometry>
			<material name="Schunk/DarkGolden" />
		</visual>
			
		<collision>
			<origin xyz="0 0 0" rpy="0 0 0" />
			<geometry>
				<mesh filename="package://schunk_description/meshes/lwa/link3.dae"/>
			</geometry>
		</collision>
	</link>	

	<!-- joint between arm_3_link and arm_4_link -->
	<joint name="${name}_4_joint" type="revolute">
		<origin xyz="0 0 0" rpy="-1.5707963 0 0 " />
		<parent link="${name}_3_link"/>
		<child link="${name}_4_link"/>
		<axis xyz="0 0 1" />
		<calibration rising="${arm_4_ref}"/>
		<dynamics damping="5" />
		<limit effort="176" velocity="2.0" lower="-2.147" upper="2.147"/>
		<safety_controller k_position="20" k_velocity="25" soft_lower_limit="${-2.147 + 0.01}" soft_upper_limit="${2.147 - 0.01}" />
	</joint>

	<link name="${name}_4_link">
		<inertial>
			<origin xyz="0 0 0" rpy="0 0 0"/>
			<!--mass value="1.2644"/-->
			<mass value="${mass_4}"/>
			<inertia ixx="0.03" ixy="0" ixz="0" iyy="0.03" iyz="0" izz="0.03" />
		</inertial>
			
		<visual>
			<origin xyz="0 0 0" rpy="0 0 0" />
			<geometry>
				<mesh filename="package://schunk_description/meshes/lwa/link4.dae" />
			</geometry>
			<material name="Schunk/DarkGolden" />
		</visual>
			
		<collision>
			<origin xyz="0 0 0" rpy="0 0 0" />
			<geometry>
				<mesh filename="package://schunk_description/meshes/lwa/link4.dae"/>
			</geometry>
		</collision>
	</link>

	<!-- joint between arm_4_link and arm_5_link -->
	<joint name="${name}_5_joint" type="revolute">
		<origin xyz="0 -0.276 0" rpy="1.5707963 0 0" />
		<parent link="${name}_4_link"/>
		<child link="${name}_5_link"/>
		<axis xyz="0 0 1" />
		<calibration rising="${arm_5_ref}"/>
		<dynamics damping="5" />
		<limit effort="41.6" velocity="2.0" lower="-3.1415926" upper="3.1415926" />
		<safety_controller k_position="20" k_velocity="25" soft_lower_limit="${-3.1415926 + 0.01}" soft_upper_limit="${3.1415926 - 0.01}"/>
	</joint>

	<link name="${name}_5_link">
		<inertial>
			<origin xyz="0 0 -0.112" rpy="0 0 0"/>
			<mass value="${mass_5}"/>
			<inertia ixx="0.03" ixy="0" ixz="0" iyy="0.03" iyz="0" izz="0.03" />
		</inertial>
			
		<visual>
			<origin xyz="0 0 0" rpy="0 0 0" />
			<geometry>
				<mesh filename="package://schunk_description/meshes/lwa/link5.dae" />
			</geometry>
			<material name="Schunk/DarkGolden" />
		</visual>
			
		<collision>
			<origin xyz="0 0 0" rpy="0 0 0" />
			<geometry>
				<mesh filename="package://schunk_description/meshes/lwa/link5.dae"/>
			</geometry>
		</collision>
	</link>

	<!-- joint between arm_5_link and arm_6_link -->
	<joint name="${name}_6_joint" type="revolute">
		<origin xyz="0 0 0" rpy="-1.5707963 0 0 " />
		<parent link="${name}_5_link"/>
		<child link="${name}_6_link"/>
		<axis xyz="0 0 1" />
		<calibration rising="${arm_6_ref}"/>
		<dynamics damping="5" />
		<limit effort="20.1" velocity="2.0" lower="-1.8" upper="1.8" />
		<safety_controller k_position="20" k_velocity="25" soft_lower_limit="${-1.8 + 0.01}" soft_upper_limit="${1.8 - 0.01}" />
	</joint>

	<link name="${name}_6_link">
		<inertial>
			<origin xyz="0 0 0" rpy="0 0 0"/>
			<mass value="${mass_6}"/>
			<inertia ixx="0.01" ixy="0" ixz="0" iyy="0.01" iyz="0" izz="0.01" />
		</inertial>
			
		<visual>
			<origin xyz="0 0 0" rpy="0 0 0" />
			<geometry>
				<mesh filename="package://schunk_description/meshes/lwa/link6.dae" />
			</geometry>
			<material name="Schunk/DarkGolden" />
		</visual>
			
		<collision>
			<origin xyz="0 0 0" rpy="0 0 0" />
			<geometry>
				<mesh filename="package://schunk_description/meshes/lwa/link6.dae"/>
			</geometry>
		</collision>
	</link>

	<!-- joint between arm_6_link and arm_7_link -->
	<joint name="${name}_7_joint" type="revolute">
		<origin xyz="0 -0.1785 0" rpy="1.5707963 0 0" />
		<parent link="${name}_6_link"/>
		<child link="${name}_7_link"/>
		<axis xyz="0 0 1" />
		<calibration rising="${arm_7_ref}"/>
		<dynamics damping="5" />
		<limit effort="9.6" velocity="2.0" lower="-3.1415926" upper="3.1415926" />
		<safety_controller k_position="20" k_velocity="25" soft_lower_limit="${-3.1415926 + 0.01}" soft_upper_limit="${3.1415926 - 0.01}"/>
	</joint>

	<link name="${name}_7_link">
		<inertial>
			<origin xyz="0 0 -0.05197" rpy="0 0 0"/>
			<mass value="${mass_7}"/>
			<inertia ixx="0.01" ixy="0" ixz="0" iyy="0.01" iyz="0" izz="0.01" />
		</inertial>
			
		<visual>
			<origin xyz="0 0 0" rpy="0 0 0" />
			<geometry>
				<mesh filename="package://schunk_description/meshes/lwa/link7.dae" />
			</geometry>
			<material name="Schunk/DarkGolden" />
		</visual>
			
		<collision>
			<origin xyz="0 0 0" rpy="0 0 0" />
			<geometry>
				<mesh filename="package://schunk_description/meshes/lwa/link7.dae"/>
			</geometry>
		</collision>
	</link>
	
	<joint name="${name}_force_sensor_joint" type="fixed">
    <parent link="${name}_7_link"/>
    <child link="${name}_force_sensor"/>
  </joint>
 
  <link name="${name}_force_sensor">
		<inertial>
			<origin xyz="0 0 0.0692" rpy="0 0 0" />
			<mass value="1.00"/>
			<inertia ixx="0.01" ixy="0" ixz="0" iyy="0.01" iyz="0" izz="0.01" />
		</inertial>
  
		<visual>
			<origin xyz="0 0 0.0692" rpy="0 0 0" />
			<geometry>
				<mesh filename="package://schunk_description/meshes/lwa/force_sensor.dae" />
			</geometry>
		</visual>

		<collision>
			<origin xyz="0 0 0.0692" rpy="0 0 0" />
			<geometry>
				<mesh filename="package://schunk_description/meshes/lwa/force_sensor.dae" />
			</geometry>
		</collision>
	</link>
	
	<xacro:schunk_lwa_gazebo name="${name}" />
	<xacro:schunk_lwa_transmission name="${name}" />

	</xacro:macro>
</robot>
